Workbook

Sheet Resumen
A1: Dashboard de cobranzas y facturación - Dataset ficticio
A3: Fecha de análisis | B3: 46204 | D3: Período | E3: Últimos 12 meses móviles
A5: Total facturado eq. ARS | B5: =SUM(FacturasTable[importe_equivalente_ars])
A6: Total cobrado eq. ARS | B6: =SUM(FacturasTable[importe_equivalente_ars])-SUM(FacturasTable[saldo_equivalente_ars])
A7: Saldo pendiente eq. ARS | B7: =SUM(FacturasTable[saldo_equivalente_ars])
A8: Saldo vencido eq. ARS | B8: =SUMIFS(FacturasTable[saldo_equivalente_ars],FacturasTable[estado],"Vencida")
A9: Facturas vencidas | B9: =COUNTIF(FacturasTable[estado],"Vencida")
A10: Saldo pendiente USD | B10: =SUMIFS(FacturasTable[saldo_pendiente],FacturasTable[moneda],"USD")
A11: Saldo pendiente ARS | B11: =SUMIFS(FacturasTable[saldo_pendiente],FacturasTable[moneda],"ARS")
A12: Días promedio de atraso | B12: =IFERROR(AVERAGEIF(FacturasTable[dias_atraso],">0",FacturasTable[dias_atraso]),0)
A15: Mes | B15: Facturado eq. ARS | C15: Cobrado eq. ARS | D15: Saldo eq. ARS | E15: Facturas | G15: Cliente | H15: Saldo eq. ARS | I15: Saldo USD | J15: Facturas vencidas
A16: 45870 | B16: =SUMIFS(FacturasTable[importe_equivalente_ars],FacturasTable[mes_vencimiento],A16) | C16: =SUMIFS(FacturasTable[importe_equivalente_ars],FacturasTable[mes_emision],A16)-SUMIFS(FacturasTable[saldo_equivalente_ars],FacturasTable[mes_emision],A16) | D16: =SUMIFS(FacturasTable[saldo_equivalente_ars],FacturasTable[mes_emision],A16) | E16: =COUNTIFS(FacturasTable[mes_emision],A16) | G16: Punto Sur S.A. | H16: =+SUMIF(FacturasTable[cliente],TopClientesTable[[#This Row],[Cliente]],FacturasTable[saldo_equivalente_ars]) | I16: =IF($G16="","",SUMIFS(FacturasTable[saldo_pendiente],FacturasTable[cliente],$G16,FacturasTable[moneda],"USD")) | J16: =+IF($G16="","",COUNTIFS(FacturasTable[cliente],$G16,FacturasTable[estado],"Vencida"))
A17: 45901 | B17: =SUMIFS(FacturasTable[importe_equivalente_ars],FacturasTable[mes_vencimiento],A17) | C17: =SUMIFS(FacturasTable[importe_equivalente_ars],FacturasTable[mes_emision],A17)-SUMIFS(FacturasTable[saldo_equivalente_ars],FacturasTable[mes_emision],A17) | D17: =SUMIFS(FacturasTable[saldo_equivalente_ars],FacturasTable[mes_emision],A17) | E17: =COUNTIFS(FacturasTable[mes_emision],A17) | G17: Faro Administrativo S.A.S. | H17: =+SUMIF(FacturasTable[cliente],TopClientesTable[[#This Row],[Cliente]],FacturasTable[saldo_equivalente_ars]) | I17: =IF($G17="","",SUMIFS(FacturasTable[saldo_pendiente],FacturasTable[cliente],$G17,FacturasTable[moneda],"USD")) | J17: =+IF($G17="","",COUNTIFS(FacturasTable[cliente],$G17,FacturasTable[estado],"Vencida"))
A18: 45931 | B18: =SUMIFS(FacturasTable[importe_equivalente_ars],FacturasTable[mes_vencimiento],A18) | C18: =SUMIFS(FacturasTable[importe_equivalente_ars],FacturasTable[mes_emision],A18)-SUMIFS(FacturasTable[saldo_equivalente_ars],FacturasTable[mes_emision],A18) | D18: =SUMIFS(FacturasTable[saldo_equivalente_ars],FacturasTable[mes_emision],A18) | E18: =COUNTIFS(FacturasTable[mes_emision],A18) | G18: Zonda Gestión S.R.L. | H18: =+SUMIF(FacturasTable[cliente],TopClientesTable[[#This Row],[Cliente]],FacturasTable[saldo_equivalente_ars]) | I18: =IF($G18="","",SUMIFS(FacturasTable[saldo_pendiente],FacturasTable[cliente],$G18,FacturasTable[moneda],"USD")) | J18: =+IF($G18="","",COUNTIFS(FacturasTable[cliente],$G18,FacturasTable[estado],"Vencida"))
A19: 45962 | B19: =SUMIFS(FacturasTable[importe_equivalente_ars],FacturasTable[mes_vencimiento],A19) | C19: =SUMIFS(FacturasTable[importe_equivalente_ars],FacturasTable[mes_emision],A19)-SUMIFS(FacturasTable[saldo_equivalente_ars],FacturasTable[mes_emision],A19) | D19: =SUMIFS(FacturasTable[saldo_equivalente_ars],FacturasTable[mes_emision],A19) | E19: =COUNTIFS(FacturasTable[mes_emision],A19) | G19: Eje Comercial S.R.L. | H19: =+SUMIF(FacturasTable[cliente],TopClientesTable[[#This Row],[Cliente]],FacturasTable[saldo_equivalente_ars]) | I19: =IF($G19="","",SUMIFS(FacturasTable[saldo_pendiente],FacturasTable[cliente],$G19,FacturasTable[moneda],"USD")) | J19: =+IF($G19="","",COUNTIFS(FacturasTable[cliente],$G19,FacturasTable[estado],"Vencida"))
A20: 45992 | B20: =SUMIFS(FacturasTable[importe_equivalente_ars],FacturasTable[mes_vencimiento],A20) | C20: =SUMIFS(FacturasTable[importe_equivalente_ars],FacturasTable[mes_emision],A20)-SUMIFS(FacturasTable[saldo_equivalente_ars],FacturasTable[mes_emision],A20) | D20: =SUMIFS(FacturasTable[saldo_equivalente_ars],FacturasTable[mes_emision],A20) | E20: =COUNTIFS(FacturasTable[mes_emision],A20) | G20: Litoral Soluciones S.R.L. | H20: =+SUMIF(FacturasTable[cliente],TopClientesTable[[#This Row],[Cliente]],FacturasTable[saldo_equivalente_ars]) | I20: =IF($G20="","",SUMIFS(FacturasTable[saldo_pendiente],FacturasTable[cliente],$G20,FacturasTable[moneda],"USD")) | J20: =+IF($G20="","",COUNTIFS(FacturasTable[cliente],$G20,FacturasTable[estado],"Vencida"))
A21: 46023 | B21: =SUMIFS(FacturasTable[importe_equivalente_ars],FacturasTable[mes_vencimiento],A21) | C21: =SUMIFS(FacturasTable[importe_equivalente_ars],FacturasTable[mes_emision],A21)-SUMIFS(FacturasTable[saldo_equivalente_ars],FacturasTable[mes_emision],A21) | D21: =SUMIFS(FacturasTable[saldo_equivalente_ars],FacturasTable[mes_emision],A21) | E21: =COUNTIFS(FacturasTable[mes_emision],A21) | G21: Delta Gestión PyME S.A. | H21: =+SUMIF(FacturasTable[cliente],TopClientesTable[[#This Row],[Cliente]],FacturasTable[saldo_equivalente_ars]) | I21: =IF($G21="","",SUMIFS(FacturasTable[saldo_pendiente],FacturasTable[cliente],$G21,FacturasTable[moneda],"USD")) | J21: =+IF($G21="","",COUNTIFS(FacturasTable[cliente],$G21,FacturasTable[estado],"Vencida"))
A22: 46054 | B22: =SUMIFS(FacturasTable[importe_equivalente_ars],FacturasTable[mes_vencimiento],A22) | C22: =SUMIFS(FacturasTable[importe_equivalente_ars],FacturasTable[mes_emision],A22)-SUMIFS(FacturasTable[saldo_equivalente_ars],FacturasTable[mes_emision],A22) | D22: =SUMIFS(FacturasTable[saldo_equivalente_ars],FacturasTable[mes_emision],A22) | E22: =COUNTIFS(FacturasTable[mes_emision],A22) | G22: Tango Gestión S.R.L. | H22: =+SUMIF(FacturasTable[cliente],TopClientesTable[[#This Row],[Cliente]],FacturasTable[saldo_equivalente_ars]) | I22: =IF($G22="","",SUMIFS(FacturasTable[saldo_pendiente],FacturasTable[cliente],$G22,FacturasTable[moneda],"USD")) | J22: =+IF($G22="","",COUNTIFS(FacturasTable[cliente],$G22,FacturasTable[estado],"Vencida"))
A23: 46082 | B23: =SUMIFS(FacturasTable[importe_equivalente_ars],FacturasTable[mes_vencimiento],A23) | C23: =SUMIFS(FacturasTable[importe_equivalente_ars],FacturasTable[mes_emision],A23)-SUMIFS(FacturasTable[saldo_equivalente_ars],FacturasTable[mes_emision],A23) | D23: =SUMIFS(FacturasTable[saldo_equivalente_ars],FacturasTable[mes_emision],A23) | E23: =COUNTIFS(FacturasTable[mes_emision],A23) | G23: Unión PyME Servicios S.A. | H23: =+SUMIF(FacturasTable[cliente],TopClientesTable[[#This Row],[Cliente]],FacturasTable[saldo_equivalente_ars]) | I23: =IF($G23="","",SUMIFS(FacturasTable[saldo_pendiente],FacturasTable[cliente],$G23,FacturasTable[moneda],"USD")) | J23: =+IF($G23="","",COUNTIFS(FacturasTable[cliente],$G23,FacturasTable[estado],"Vencida"))
A24: 46113 | B24: =SUMIFS(FacturasTable[importe_equivalente_ars],FacturasTable[mes_vencimiento],A24) | C24: =SUMIFS(FacturasTable[importe_equivalente_ars],FacturasTable[mes_emision],A24)-SUMIFS(FacturasTable[saldo_equivalente_ars],FacturasTable[mes_emision],A24) | D24: =SUMIFS(FacturasTable[saldo_equivalente_ars],FacturasTable[mes_emision],A24) | E24: =COUNTIFS(FacturasTable[mes_emision],A24) | G24: Valle Operativo S.R.L. | H24: =+SUMIF(FacturasTable[cliente],TopClientesTable[[#This Row],[Cliente]],FacturasTable[saldo_equivalente_ars]) | I24: =IF($G24="","",SUMIFS(FacturasTable[saldo_pendiente],FacturasTable[cliente],$G24,FacturasTable[moneda],"USD")) | J24: =+IF($G24="","",COUNTIFS(FacturasTable[cliente],$G24,FacturasTable[estado],"Vencida"))
A25: 46143 | B25: =SUMIFS(FacturasTable[importe_equivalente_ars],FacturasTable[mes_vencimiento],A25) | C25: =SUMIFS(FacturasTable[importe_equivalente_ars],FacturasTable[mes_emision],A25)-SUMIFS(FacturasTable[saldo_equivalente_ars],FacturasTable[mes_emision],A25) | D25: =SUMIFS(FacturasTable[saldo_equivalente_ars],FacturasTable[mes_emision],A25) | E25: =COUNTIFS(FacturasTable[mes_emision],A25) | G25: Horizonte Servicios S.R.L. | H25: =+SUMIF(FacturasTable[cliente],TopClientesTable[[#This Row],[Cliente]],FacturasTable[saldo_equivalente_ars]) | I25: =IF($G25="","",SUMIFS(FacturasTable[saldo_pendiente],FacturasTable[cliente],$G25,FacturasTable[moneda],"USD")) | J25: =+IF($G25="","",COUNTIFS(FacturasTable[cliente],$G25,FacturasTable[estado],"Vencida"))
A26: 46174 | B26: =SUMIFS(FacturasTable[importe_equivalente_ars],FacturasTable[mes_vencimiento],A26) | C26: =SUMIFS(FacturasTable[importe_equivalente_ars],FacturasTable[mes_emision],A26)-SUMIFS(FacturasTable[saldo_equivalente_ars],FacturasTable[mes_emision],A26) | D26: =SUMIFS(FacturasTable[saldo_equivalente_ars],FacturasTable[mes_emision],A26) | E26: =COUNTIFS(FacturasTable[mes_emision],A26)
A27: 46204 | B27: =SUMIFS(FacturasTable[importe_equivalente_ars],FacturasTable[mes_vencimiento],A27) | C27: =SUMIFS(FacturasTable[importe_equivalente_ars],FacturasTable[mes_emision],A27)-SUMIFS(FacturasTable[saldo_equivalente_ars],FacturasTable[mes_emision],A27) | D27: =SUMIFS(FacturasTable[saldo_equivalente_ars],FacturasTable[mes_emision],A27) | E27: =COUNTIFS(FacturasTable[mes_emision],A27)

Sheet Facturas
A1: id_factura | B1: fecha_emision | C1: fecha_vencimiento | D1: fecha_pago | E1: id_cliente | F1: cliente | G1: tipo_cliente | H1: id_servicio | I1: tipo_servicio | J1: moneda | K1: importe_facturado | L1: importe_cobrado | M1: saldo_pendiente | N1: tipo_cambio | O1: importe_equivalente_ars | P1: saldo_equivalente_ars | Q1: estado | R1: dias_atraso | S1: prioridad_cobranza | T1: responsable | U1: proxima_accion | V1: observaciones | W1: mes_emision | X1: mes_vencimiento | Y1: trimestre | Z1: vencida_si_no | AA1: parcial_si_no | AB1: exposicion_usd_si_no
A2: FAC-00008 | B2: 45870 | C2: 45930 | D2: 45962 | E2: CL-006 | F2: Delta Gestión PyME S.A. | G2: PyME servicios recurrentes | H2: SRV-001 | I2: Abono mensual administrativo | J2: ARS | K2: 933000 | L2: 933000 | M2: 0 | N2: 1297 | O2: 0 | P2: 0 | Q2: =IF(M9<=0,"Cobrada",IF(L9>0,"Parcial",IF(C9<Resumen!$B$3,"Vencida",IF(C9<=Resumen!$B$3+15,"Por vencer","Pendiente")))) | R2: 0 | S2: =IF(M9<=0,"Sin prioridad",IF(R9>60,"Alta",IF(R9>30,"Media",IF(C9<=Resumen!$B$3+15,"Media","Baja")))) | T2: Ana | U2: Sin acción | V2: En seguimiento administrativo | Y2: 2025-T3 | Z2: =IF(AND(M9>0,C9<Resumen!$B$3),"Sí","No") | AA2: =IF(AND(L9>0,M9>0),"Sí","No") | AB2: =IF(J9="USD","Sí","No")
A3: FAC-00022 | B3: 45876 | C3: 45891 | D3: 45899 | E3: CL-001 | F3: Altos del Centro S.R.L. | G3: PyME servicios recurrentes | H3: SRV-001 | I3: Abono mensual administrativo | J3: USD | K3: 300 | L3: 300 | M3: 0 | N3: 1297 | O3: 0 | P3: 0 | Q3: =IF(M23<=0,"Cobrada",IF(L23>0,"Parcial",IF(C23<Resumen!$B$3,"Vencida",IF(C23<=Resumen!$B$3+15,"Por vencer","Pendiente")))) | R3: 0 | S3: =IF(M23<=0,"Sin prioridad",IF(R23>60,"Alta",IF(R23>30,"Media",IF(C23<=Resumen!$B$3+15,"Media","Baja")))) | T3: Carlos | U3: Sin acción | V3: Pendiente de confirmación de pago | Y3: 2025-T3 | Z3: =IF(AND(M23>0,C23<Resumen!$B$3),"Sí","No") | AA3: =IF(AND(L23>0,M23>0),"Sí","No") | AB3: =IF(J23="USD","Sí","No")
A4: FAC-00005 | B4: 45878 | C4: 45923 | D4: 45927 | E4: CL-007 | F4: Eje Comercial S.R.L. | G4: PyME servicios recurrentes | H4: SRV-001 | I4: Abono mensual administrativo | J4: ARS | K4: 402000 | L4: 402000 | M4: 0 | N4: 1297 | O4: 0 | P4: 0 | Q4: =IF(M6<=0,"Cobrada",IF(L6>0,"Parcial",IF(C6<Resumen!$B$3,"Vencida",IF(C6<=Resumen!$B$3+15,"Por vencer","Pendiente")))) | R4: 0 | S4: =IF(M6<=0,"Sin prioridad",IF(R6>60,"Alta",IF(R6>30,"Media",IF(C6<=Resumen!$B$3+15,"Media","Baja")))) | T4: Matías | U4: Sin acción | V4: Pago prometido para próxima semana | Y4: 2025-T3 | Z4: =IF(AND(M6>0,C6<Resumen!$B$3),"Sí","No") | AA4: =IF(AND(L6>0,M6>0),"Sí","No") | AB4: =IF(J6="USD","Sí","No")
A5: FAC-00012 | B5: 45878 | C5: 45908 | D5: 45912 | E5: CL-009 | F5: Grupo Nexo PyME S.A. | G5: PyME servicios recurrentes | H5: SRV-002 | I5: Soporte operativo | J5: ARS | K5: 817000 | L5: 817000 | M5: 0 | N5: 1297 | O5: 0 | P5: 0 | Q5: =IF(M13<=0,"Cobrada",IF(L13>0,"Parcial",IF(C13<Resumen!$B$3,"Vencida",IF(C13<=Resumen!$B$3+15,"Por vencer","Pendiente")))) | R5: 0 | S5: =IF(M13<=0,"Sin prioridad",IF(R13>60,"Alta",IF(R13>30,"Media",IF(C13<=Resumen!$B$3+15,"Media","Baja")))) | T5: Ana | U5: Sin acción | Y5: 2025-T3 | Z5: =IF(AND(M13>0,C13<Resumen!$B$3),"Sí","No") | AA5: =IF(AND(L13>0,M13>0),"Sí","No") | AB5: =IF(J13="USD","Sí","No")
A6: FAC-00023 | B6: 45878 | C6: 45923 | D6: 45923 | E6: CL-014 | F6: Norte Gestión Integral S.R.L. | G6: PyME servicios recurrentes | H6: SRV-003 | I6: Consultoría de gestión | J6: USD | K6: 2300 | L6: 2300 | M6: 0 | N6: 1297 | O6: 0 | P6: 0 | Q6: =IF(M24<=0,"Cobrada",IF(L24>0,"Parcial",IF(C24<Resumen!$B$3,"Vencida",IF(C24<=Resumen!$B$3+15,"Por vencer","Pendiente")))) | R6: 0 | S6: =IF(M24<=0,"Sin prioridad",IF(R24>60,"Alta",IF(R24>30,"Media",IF(C24<=Resumen!$B$3+15,"Media","Baja")))) | T6: Carlos | U6: Sin acción | V6: Pendiente de confirmación de pago | Y6: 2025-T3 | Z6: =IF(AND(M24>0,C24<Resumen!$B$3),"Sí","No") | AA6: =IF(AND(L24>0,M24>0),"Sí","No") | AB6: =IF(J24="USD","Sí","No")
A7: FAC-00003 | B7: 45880 | C7: 45895 | D7: 45891 | E7: CL-011 | F7: Impulso Gestión S.A.S. | G7: PyME servicios recurrentes | H7: SRV-002 | I7: Soporte operativo | J7: ARS | K7: 447000 | L7: 447000 | M7: 0 | N7: 1297 | O7: 0 | P7: 0 | Q7: =IF(M4<=0,"Cobrada",IF(L4>0,"Parcial",IF(C4<Resumen!$B$3,"Vencida",IF(C4<=Resumen!$B$3+15,"Por vencer","Pendiente")))) | R7: 0 | S7: =IF(M4<=0,"Sin prioridad",IF(R4>60,"Alta",IF(R4>30,"Media",IF(C4<=Resumen!$B$3+15,"Media","Baja")))) | T7: Carlos | U7: Sin acción | V7: Cliente solicita reenvío de factura | Y7: 2025-T3 | Z7: =IF(AND(M4>0,C4<Resumen!$B$3),"Sí","No") | AA7: =IF(AND(L4>0,M4>0),"Sí","No") | AB7: =IF(J4="USD","Sí","No")
A8: FAC-00017 | B8: 45880 | C8: 45895 | D8: 45939 | E8: CL-017 | F8: Punto Sur S.A. | G8: PyME servicios recurrentes | H8: SRV-001 | I8: Abono mensual administrativo | J8: ARS | K8: 503000 | L8: 503000 | M8: 0 | N8: 1297 | O8: 0 | P8: 0 | Q8: =IF(M18<=0,"Cobrada",IF(L18>0,"Parcial",IF(C18<Resumen!$B$3,"Vencida",IF(C18<=Resumen!$B$3+15,"Por vencer","Pendiente")))) | R8: 0 | S8: =IF(M18<=0,"Sin prioridad",IF(R18>60,"Alta",IF(R18>30,"Media",IF(C18<=Resumen!$B$3+15,"Media","Baja")))) | T8: Sofía | U8: Sin acción | V8: Pago prometido para próxima semana | Y8: 2025-T3 | Z8: =IF(AND(M18>0,C18<Resumen!$B$3),"Sí","No") | AA8: =IF(AND(L18>0,M18>0),"Sí","No") | AB8: =IF(J18="USD","Sí","No")
A9: FAC-00019 | B9: 45880 | C9: 45925 | D9: 45962 | E9: CL-024 | F9: Zonda Gestión S.R.L. | G9: PyME servicios recurrentes | H9: SRV-005 | I9: Servicio extraordinario puntual | J9: ARS | K9: 742000 | L9: 299304.39 | M9: 0 | N9: 1297 | O9: 0 | P9: 0 | Q9: =IF(M20<=0,"Cobrada",IF(L20>0,"Parcial",IF(C20<Resumen!$B$3,"Vencida",IF(C20<=Resumen!$B$3+15,"Por vencer","Pendiente")))) | R9: 0 | S9: =IF(M20<=0,"Sin prioridad",IF(R20>60,"Alta",IF(R20>30,"Media",IF(C20<=Resumen!$B$3+15,"Media","Baja")))) | T9: Sofía | U9: Reclamar saldo parcial | Y9: 2025-T3 | Z9: =IF(AND(M20>0,C20<Resumen!$B$3),"Sí","No") | AA9: =IF(AND(L20>0,M20>0),"Sí","No") | AB9: =IF(J20="USD","Sí","No")
A10: FAC-00009 | B10: 45881 | C10: 45926 | E10: CL-007 | F10: Eje Comercial S.R.L. | G10: PyME servicios recurrentes | H10: SRV-002 | I10: Soporte operativo | J10: ARS | K10: 515000 | L10: 0 | M10: 0 | N10: 1297 | O10: 0 | P10: 0 | Q10: =IF(M10<=0,"Cobrada",IF(L10>0,"Parcial",IF(C10<Resumen!$B$3,"Vencida",IF(C10<=Resumen!$B$3+15,"Por vencer","Pendiente")))) | R10: 0 | S10: =IF(M10<=0,"Sin prioridad",IF(R10>60,"Alta",IF(R10>30,"Media",IF(C10<=Resumen!$B$3+15,"Media","Baja")))) | T10: Matías | U10: Escalar gestión | V10: Sin respuesta del cliente | Y10: 2025-T3 | Z10: =IF(AND(M10>0,C10<Resumen!$B$3),"Sí","No") | AA10: =IF(AND(L10>0,M10>0),"Sí","No") | AB10: =IF(J10="USD","Sí","No")
A11: FAC-00013 | B11: 45882 | C11: 45927 | D11: 45961 | E11: CL-010 | F11: Horizonte Servicios S.R.L. | G11: PyME servicios recurrentes | H11: SRV-002 | I11: Soporte operativo | J11: ARS | K11: 752000 | L11: 280330.49 | M11: 0 | N11: 1297 | O11: 0 | P11: 0 | Q11: =IF(M14<=0,"Cobrada",IF(L14>0,"Parcial",IF(C14<Resumen!$B$3,"Vencida",IF(C14<=Resumen!$B$3+15,"Por vencer","Pendiente")))) | R11: 0 | S11: =IF(M14<=0,"Sin prioridad",IF(R14>60,"Alta",IF(R14>30,"Media",IF(C14<=Resumen!$B$3+15,"Media","Baja")))) | T11: Matías | U11: Reclamar saldo parcial | V11: Pendiente de confirmación de pago | Y11: 2025-T3 | Z11: =IF(AND(M14>0,C14<Resumen!$B$3),"Sí","No") | AA11: =IF(AND(L14>0,M14>0),"Sí","No") | AB11: =IF(J14="USD","Sí","No")
A12: FAC-00014 | B12: 45882 | C12: 45897 | D12: 45914 | E12: CL-003 | F12: Arco Norte S.R.L. | G12: PyME servicios recurrentes | H12: SRV-005 | I12: Servicio extraordinario puntual | J12: ARS | K12: 1136000 | L12: 1136000 | M12: 0 | N12: 1297 | O12: 0 | P12: 0 | Q12: =IF(M15<=0,"Cobrada",IF(L15>0,"Parcial",IF(C15<Resumen!$B$3,"Vencida",IF(C15<=Resumen!$B$3+15,"Por vencer","Pendiente")))) | R12: 0 | S12: =IF(M15<=0,"Sin prioridad",IF(R15>60,"Alta",IF(R15>30,"Media",IF(C15<=Resumen!$B$3+15,"Media","Baja")))) | T12: Sofía | U12: Sin acción | V12: Pendiente de confirmación de pago | Y12: 2025-T3 | Z12: =IF(AND(M15>0,C15<Resumen!$B$3),"Sí","No") | AA12: =IF(AND(L15>0,M15>0),"Sí","No") | AB12: =IF(J15="USD","Sí","No")
A13: FAC-00020 | B13: 45882 | C13: 45897 | D13: 45909 | E13: CL-003 | F13: Arco Norte S.R.L. | G13: PyME servicios recurrentes | H13: SRV-001 | I13: Abono mensual administrativo | J13: ARS | K13: 404000 | L13: 404000 | M13: 0 | N13: 1297 | O13: 0 | P13: 0 | Q13: =IF(M21<=0,"Cobrada",IF(L21>0,"Parcial",IF(C21<Resumen!$B$3,"Vencida",IF(C21<=Resumen!$B$3+15,"Por vencer","Pendiente")))) | R13: 0 | S13: =IF(M21<=0,"Sin prioridad",IF(R21>60,"Alta",IF(R21>30,"Media",IF(C21<=Resumen!$B$3+15,"Media","Baja")))) | T13: Sofía | U13: Sin acción | V13: Sin respuesta del cliente | Y13: 2025-T3 | Z13: =IF(AND(M21>0,C21<Resumen!$B$3),"Sí","No") | AA13: =IF(AND(L21>0,M21>0),"Sí","No") | AB13: =IF(J21="USD","Sí","No")
A14: FAC-00024 | B14: 45882 | C14: 45927 | E14: CL-010 | F14: Horizonte Servicios S.R.L. | G14: PyME servicios recurrentes | H14: SRV-001 | I14: Abono mensual administrativo | J14: ARS | K14: 521000 | L14: 0 | M14: 0 | N14: 1297 | O14: 0 | P14: 0 | Q14: =IF(M25<=0,"Cobrada",IF(L25>0,"Parcial",IF(C25<Resumen!$B$3,"Vencida",IF(C25<=Resumen!$B$3+15,"Por vencer","Pendiente")))) | R14: 0 | S14: =IF(M25<=0,"Sin prioridad",IF(R25>60,"Alta",IF(R25>30,"Media",IF(C25<=Resumen!$B$3+15,"Media","Baja")))) | T14: Matías | U14: Escalar gestión | V14: Cliente solicita reenvío de factura | Y14: 2025-T3 | Z14: =IF(AND(M25>0,C25<Resumen!$B$3),"Sí","No") | AA14: =IF(AND(L25>0,M25>0),"Sí","No") | AB14: =IF(J25="USD","Sí","No")
A15: FAC-00011 | B15: 45883 | C15: 45913 | D15: 45918 | E15: CL-009 | F15: Grupo Nexo PyME S.A. | G15: PyME servicios recurrentes | H15: SRV-001 | I15: Abono mensual administrativo | J15: ARS | K15: 899000 | L15: 899000 | M15: 0 | N15: 1297 | O15: 0 | P15: 0 | Q15: =IF(M12<=0,"Cobrada",IF(L12>0,"Parcial",IF(C12<Resumen!$B$3,"Vencida",IF(C12<=Resumen!$B$3+15,"Por vencer","Pendiente")))) | R15: 0 | S15: =IF(M12<=0,"Sin prioridad",IF(R12>60,"Alta",IF(R12>30,"Media",IF(C12<=Resumen!$B$3+15,"Media","Baja")))) | T15: Ana | U15: Sin acción | Y15: 2025-T3 | Z15: =IF(AND(M12>0,C12<Resumen!$B$3),"Sí","No") | AA15: =IF(AND(L12>0,M12>0),"Sí","No") | AB15: =IF(J12="USD","Sí","No")
A16: FAC-00016 | B16: 45883 | C16: 45898 | D16: 45921 | E16: CL-017 | F16: Punto Sur S.A. | G16: PyME servicios recurrentes | H16: SRV-001 | I16: Abono mensual administrativo | J16: ARS | K16: 825000 | L16: 825000 | M16: 0 | N16: 1297 | O16: 0 | P16: 0 | Q16: =IF(M17<=0,"Cobrada",IF(L17>0,"Parcial",IF(C17<Resumen!$B$3,"Vencida",IF(C17<=Resumen!$B$3+15,"Por vencer","Pendiente")))) | R16: 0 | S16: =IF(M17<=0,"Sin prioridad",IF(R17>60,"Alta",IF(R17>30,"Media",IF(C17<=Resumen!$B$3+15,"Media","Baja")))) | T16: Sofía | U16: Sin acción | V16: Cliente solicita reenvío de factura | Y16: 2025-T3 | Z16: =IF(AND(M17>0,C17<Resumen!$B$3),"Sí","No") | AA16: =IF(AND(L17>0,M17>0),"Sí","No") | AB16: =IF(J17="USD","Sí","No")
A17: FAC-00015 | B17: 45886 | C17: 45916 | D17: 45911 | E17: CL-009 | F17: Grupo Nexo PyME S.A. | G17: PyME servicios recurrentes | H17: SRV-003 | I17: Consultoría de gestión | J17: USD | K17: 1100 | L17: 1100 | M17: 0 | N17: 1297 | O17: 0 | P17: 0 | Q17: =IF(M16<=0,"Cobrada",IF(L16>0,"Parcial",IF(C16<Resumen!$B$3,"Vencida",IF(C16<=Resumen!$B$3+15,"Por vencer","Pendiente")))) | R17: 0 | S17: =IF(M16<=0,"Sin prioridad",IF(R16>60,"Alta",IF(R16>30,"Media",IF(C16<=Resumen!$B$3+15,"Media","Baja")))) | T17: Ana | U17: Sin acción | Y17: 2025-T3 | Z17: =IF(AND(M16>0,C16<Resumen!$B$3),"Sí","No") | AA17: =IF(AND(L16>0,M16>0),"Sí","No") | AB17: =IF(J16="USD","Sí","No")
A18: FAC-00004 | B18: 45890 | C18: 45905 | D18: 45900 | E18: CL-011 | F18: Impulso Gestión S.A.S. | G18: PyME servicios recurrentes | H18: SRV-001 | I18: Abono mensual administrativo | J18: ARS | K18: 654000 | L18: 654000 | M18: 0 | N18: 1297 | O18: 0 | P18: 0 | Q18: =IF(M5<=0,"Cobrada",IF(L5>0,"Parcial",IF(C5<Resumen!$B$3,"Vencida",IF(C5<=Resumen!$B$3+15,"Por vencer","Pendiente")))) | R18: 0 | S18: =IF(M5<=0,"Sin prioridad",IF(R5>60,"Alta",IF(R5>30,"Media",IF(C5<=Resumen!$B$3+15,"Media","Baja")))) | T18: Carlos | U18: Sin acción | V18: Pago prometido para próxima semana | Y18: 2025-T3 | Z18: =IF(AND(M5>0,C5<Resumen!$B$3),"Sí","No") | AA18: =IF(AND(L5>0,M5>0),"Sí","No") | AB18: =IF(J5="USD","Sí","No")
A19: FAC-00010 | B19: 45890 | C19: 45905 | D19: 45909 | E19: CL-004 | F19: Base Sur Servicios S.A.S. | G19: PyME servicios recurrentes | H19: SRV-001 | I19: Abono mensual administrativo | J19: ARS | K19: 356000 | L19: 356000 | M19: 0 | N19: 1297 | O19: 0 | P19: 0 | Q19: =IF(M11<=0,"Cobrada",IF(L11>0,"Parcial",IF(C11<Resumen!$B$3,"Vencida",IF(C11<=Resumen!$B$3+15,"Por vencer","Pendiente")))) | R19: 0 | S19: =IF(M11<=0,"Sin prioridad",IF(R11>60,"Alta",IF(R11>30,"Media",IF(C11<=Resumen!$B$3+15,"Media","Baja")))) | T19: Ana | U19: Sin acción | Y19: 2025-T3 | Z19: =IF(AND(M11>0,C11<Resumen!$B$3),"Sí","No") | AA19: =IF(AND(L11>0,M11>0),"Sí","No") | AB19: =IF(J11="USD","Sí","No")
A20: FAC-00006 | B20: 45892 | C20: 45907 | E20: CL-023 | F20: Vector Administración S.A.S. | G20: PyME servicios recurrentes | H20: SRV-001 | I20: Abono mensual administrativo | J20: ARS | K20: 695000 | L20: 0 | M20: 0 | N20: 1297 | O20: 0 | P20: 0 | Q20: =IF(M7<=0,"Cobrada",IF(L7>0,"Parcial",IF(C7<Resumen!$B$3,"Vencida",IF(C7<=Resumen!$B$3+15,"Por vencer","Pendiente")))) | R20: 0 | S20: =IF(M7<=0,"Sin prioridad",IF(R7>60,"Alta",IF(R7>30,"Media",IF(C7<=Resumen!$B$3+15,"Media","Baja")))) | T20: Ana | U20: Llamar al cliente | V20: En seguimiento administrativo | Y20: 2025-T3 | Z20: =IF(AND(M7>0,C7<Resumen!$B$3),"Sí","No") | AA20: =IF(AND(L7>0,M7>0),"Sí","No") | AB20: =IF(J7="USD","Sí","No")
A21: FAC-00021 | B21: 45892 | C21: 45952 | E21: CL-006 | F21: Delta Gestión PyME S.A. | G21: PyME servicios recurrentes | H21: SRV-003 | I21: Consultoría de gestión | J21: ARS | K21: 1586000 | L21: 0 | M21: 0 | N21: 1297 | O21: 0 | P21: 0 | Q21: =IF(M22<=0,"Cobrada",IF(L22>0,"Parcial",IF(C22<Resumen!$B$3,"Vencida",IF(C22<=Resumen!$B$3+15,"Por vencer","Pendiente")))) | R21: 0 | S21: =IF(M22<=0,"Sin prioridad",IF(R22>60,"Alta",IF(R22>30,"Media",IF(C22<=Resumen!$B$3+15,"Media","Baja")))) | T21: Ana | U21: Reenviar factura | V21: En seguimiento administrativo | Y21: 2025-T3 | Z21: =IF(AND(M22>0,C22<Resumen!$B$3),"Sí","No") | AA21: =IF(AND(L22>0,M22>0),"Sí","No") | AB21: =IF(J22="USD","Sí","No")
A22: FAC-00002 | B22: 45894 | C22: 45909 | D22: 45924 | E22: CL-001 | F22: Altos del Centro S.R.L. | G22: PyME servicios recurrentes | H22: SRV-001 | I22: Abono mensual administrativo | J22: ARS | K22: 668000 | L22: 668000 | M22: 0 | N22: 1297 | O22: 0 | P22: 0 | Q22: =IF(M3<=0,"Cobrada",IF(L3>0,"Parcial",IF(C3<Resumen!$B$3,"Vencida",IF(C3<=Resumen!$B$3+15,"Por vencer","Pendiente")))) | R22: 0 | S22: =IF(M3<=0,"Sin prioridad",IF(R3>60,"Alta",IF(R3>30,"Media",IF(C3<=Resumen!$B$3+15,"Media","Baja")))) | T22: Carlos | U22: Sin acción | V22: Sin respuesta del cliente | Y22: 2025-T3 | Z22: =IF(AND(M3>0,C3<Resumen!$B$3),"Sí","No") | AA22: =IF(AND(L3>0,M3>0),"Sí","No") | AB22: =IF(J3="USD","Sí","No")
A23: FAC-00007 | B23: 45895 | C23: 45925 | E23: CL-008 | F23: Faro Administrativo S.A.S. | G23: PyME servicios recurrentes | H23: SRV-002 | I23: Soporte operativo | J23: ARS | K23: 643000 | L23: 0 | M23: 0 | N23: 1297 | O23: 0 | P23: 0 | Q23: =IF(M8<=0,"Cobrada",IF(L8>0,"Parcial",IF(C8<Resumen!$B$3,"Vencida",IF(C8<=Resumen!$B$3+15,"Por vencer","Pendiente")))) | R23: 0 | S23: =IF(M8<=0,"Sin prioridad",IF(R8>60,"Alta",IF(R8>30,"Media",IF(C8<=Resumen!$B$3+15,"Media","Baja")))) | T23: Sofía | U23: Reenviar factura | Y23: 2025-T3 | Z23: =IF(AND(M8>0,C8<Resumen!$B$3),"Sí","No") | AA23: =IF(AND(L8>0,M8>0),"Sí","No") | AB23: =IF(J8="USD","Sí","No")
A24: FAC-00018 | B24: 45895 | C24: 45925 | D24: 45942 | E24: CL-021 | F24: Unión PyME Servicios S.A. | G24: PyME servicios recurrentes | H24: SRV-003 | I24: Consultoría de gestión | J24: USD | K24: 1800 | L24: 1800 | M24: 0 | N24: 1297 | O24: 0 | P24: 0 | Q24: =IF(M19<=0,"Cobrada",IF(L19>0,"Parcial",IF(C19<Resumen!$B$3,"Vencida",IF(C19<=Resumen!$B$3+15,"Por vencer","Pendiente")))) | R24: 0 | S24: =IF(M19<=0,"Sin prioridad",IF(R19>60,"Alta",IF(R19>30,"Media",IF(C19<=Resumen!$B$3+15,"Media","Baja")))) | T24: Ana | U24: Sin acción | V24: Pendiente de confirmación de pago | Y24: 2025-T3 | Z24: =IF(AND(M19>0,C19<Resumen!$B$3),"Sí","No") | AA24: =IF(AND(L19>0,M19>0),"Sí","No") | AB24: =IF(J19="USD","Sí","No")
A25: FAC-00001 | B25: 45897 | C25: 45912 | D25: 45934 | E25: CL-017 | F25: Punto Sur S.A. | G25: PyME servicios recurrentes | H25: SRV-002 | I25: Soporte operativo | J25: USD | K25: 650 | L25: 650 | M25: 0 | N25: 1297 | O25: 0 | P25: 0 | Q25: =IF(M2<=0,"Cobrada",IF(L2>0,"Parcial",IF(C2<Resumen!$B$3,"Vencida",IF(C2<=Resumen!$B$3+15,"Por vencer","Pendiente")))) | R25: 0 | S25: =IF(M2<=0,"Sin prioridad",IF(R2>60,"Alta",IF(R2>30,"Media",IF(C2<=Resumen!$B$3+15,"Media","Baja")))) | T25: Sofía | U25: Sin acción | V25: En seguimiento administrativo | Y25: 2025-T3 | Z25: =IF(AND(M2>0,C2<Resumen!$B$3),"Sí","No") | AA25: =IF(AND(L2>0,M2>0),"Sí","No") | AB25: =IF(J2="USD","Sí","No")
A26: FAC-00033 | B26: 45902 | C26: 45947 | D26: 45950 | E26: CL-018 | F26: Río Claro Servicios S.R.L. | G26: PyME servicios recurrentes | H26: SRV-002 | I26: Soporte operativo | J26: USD | K26: 250 | L26: 250 | M26: 0 | N26: 1330 | O26: 0 | P26: 0 | Q26: =IF(M34<=0,"Cobrada",IF(L34>0,"Parcial",IF(C34<Resumen!$B$3,"Vencida",IF(C34<=Resumen!$B$3+15,"Por vencer","Pendiente")))) | R26: 0 | S26: =IF(M34<=0,"Sin prioridad",IF(R34>60,"Alta",IF(R34>30,"Media",IF(C34<=Resumen!$B$3+15,"Media","Baja")))) | T26: Ana | U26: Sin acción | V26: En seguimiento administrativo | Y26: 2025-T3 | Z26: =IF(AND(M34>0,C34<Resumen!$B$3),"Sí","No") | AA26: =IF(AND(L34>0,M34>0),"Sí","No") | AB26: =IF(J34="USD","Sí","No")
A27: FAC-00044 | B27: 45902 | C27: 45932 | D27: 45932 | E27: CL-009 | F27: Grupo Nexo PyME S.A. | G27: PyME servicios recurrentes | H27: SRV-001 | I27: Abono mensual administrativo | J27: ARS | K27: 926000 | L27: 926000 | M27: 0 | N27: 1330 | O27: 0 | P27: 0 | Q27: =IF(M45<=0,"Cobrada",IF(L45>0,"Parcial",IF(C45<Resumen!$B$3,"Vencida",IF(C45<=Resumen!$B$3+15,"Por vencer","Pendiente")))) | R27: 0 | S27: =IF(M45<=0,"Sin prioridad",IF(R45>60,"Alta",IF(R45>30,"Media",IF(C45<=Resumen!$B$3+15,"Media","Baja")))) | T27: Ana | U27: Sin acción | V27: En seguimiento administrativo | Y27: 2025-T3 | Z27: =IF(AND(M45>0,C45<Resumen!$B$3),"Sí","No") | AA27: =IF(AND(L45>0,M45>0),"Sí","No") | AB27: =IF(J45="USD","Sí","No")
A28: FAC-00031 | B28: 45903 | C28: 45918 | D28: 45934 | E28: CL-017 | F28: Punto Sur S.A. | G28: PyME servicios recurrentes | H28: SRV-001 | I28: Abono mensual administrativo | J28: ARS | K28: 405000 | L28: 405000 | M28: 0 | N28: 1330 | O28: 0 | P28: 0 | Q28: =IF(M32<=0,"Cobrada",IF(L32>0,"Parcial",IF(C32<Resumen!$B$3,"Vencida",IF(C32<=Resumen!$B$3+15,"Por vencer","Pendiente")))) | R28: 0 | S28: =IF(M32<=0,"Sin prioridad",IF(R32>60,"Alta",IF(R32>30,"Media",IF(C32<=Resumen!$B$3+15,"Media","Baja")))) | T28: Sofía | U28: Sin acción | V28: En seguimiento administrativo | Y28: 2025-T3 | Z28: =IF(AND(M32>0,C32<Resumen!$B$3),"Sí","No") | AA28: =IF(AND(L32>0,M32>0),"Sí","No") | AB28: =IF(J32="USD","Sí","No")
A29: FAC-00029 | B29: 45906 | C29: 45936 | D29: 45959 | E29: CL-019 | F29: Sierra Norte S.A.S. | G29: PyME servicios recurrentes | H29: SRV-001 | I29: Abono mensual administrativo | J29: ARS | K29: 942000 | L29: 268010.92 | M29: 0 | N29: 1330 | O29: 0 | P29: 0 | Q29: =IF(M30<=0,"Cobrada",IF(L30>0,"Parcial",IF(C30<Resumen!$B$3,"Vencida",IF(C30<=Resumen!$B$3+15,"Por vencer","Pendiente")))) | R29: 0 | S29: =IF(M30<=0,"Sin prioridad",IF(R30>60,"Alta",IF(R30>30,"Media",IF(C30<=Resumen!$B$3+15,"Media","Baja")))) | T29: Carlos | U29: Reclamar saldo parcial | V29: Sin respuesta del cliente | Y29: 2025-T3 | Z29: =IF(AND(M30>0,C30<Resumen!$B$3),"Sí","No") | AA29: =IF(AND(L30>0,M30>0),"Sí","No") | AB29: =IF(J30="USD","Sí","No")
A30: FAC-00047 | B30: 45906 | C30: 45921 | E30: CL-023 | F30: Vector Administración S.A.S. | G30: PyME servicios recurrentes | H30: SRV-001 | I30: Abono mensual administrativo | J30: USD | K30: 750 | L30: 0 | M30: 0 | N30: 1330 | O30: 0 | P30: 0 | Q30: =IF(M48<=0,"Cobrada",IF(L48>0,"Parcial",IF(C48<Resumen!$B$3,"Vencida",IF(C48<=Resumen!$B$3+15,"Por vencer","Pendiente")))) | R30: 0 | S30: =IF(M48<=0,"Sin prioridad",IF(R48>60,"Alta",IF(R48>30,"Media",IF(C48<=Resumen!$B$3+15,"Media","Baja")))) | T30: Ana | U30: Llamar al cliente | Y30: 2025-T3 | Z30: =IF(AND(M48>0,C48<Resumen!$B$3),"Sí","No") | AA30: =IF(AND(L48>0,M48>0),"Sí","No") | AB30: =IF(J48="USD","Sí","No")
A31: FAC-00035 | B31: 45907 | C31: 45922 | D31: 45949 | E31: CL-017 | F31: Punto Sur S.A. | G31: PyME servicios recurrentes | H31: SRV-003 | I31: Consultoría de gestión | J31: USD | K31: 1700 | L31: 1700 | M31: 0 | N31: 1330 | O31: 0 | P31: 0 | Q31: =IF(M36<=0,"Cobrada",IF(L36>0,"Parcial",IF(C36<Resumen!$B$3,"Vencida",IF(C36<=Resumen!$B$3+15,"Por vencer","Pendiente")))) | R31: 0 | S31: =IF(M36<=0,"Sin prioridad",IF(R36>60,"Alta",IF(R36>30,"Media",IF(C36<=Resumen!$B$3+15,"Media","Baja")))) | T31: Sofía | U31: Sin acción | V31: Pendiente de confirmación de pago | Y31: 2025-T3 | Z31: =IF(AND(M36>0,C36<Resumen!$B$3),"Sí","No") | AA31: =IF(AND(L36>0,M36>0),"Sí","No") | AB31: =IF(J36="USD","Sí","No")
A32: FAC-00037 | B32: 45907 | C32: 45952 | D32: 45953 | E32: CL-018 | F32: Río Claro Servicios S.R.L. | G32: PyME servicios recurrentes | H32: SRV-001 | I32: Abono mensual administrativo | J32: ARS | K32: 821000 | L32: 821000 | M32: 0 | N32: 1330 | O32: 0 | P32: 0 | Q32: =IF(M38<=0,"Cobrada",IF(L38>0,"Parcial",IF(C38<Resumen!$B$3,"Vencida",IF(C38<=Resumen!$B$3+15,"Por vencer","Pendiente")))) | R32: 0 | S32: =IF(M38<=0,"Sin prioridad",IF(R38>60,"Alta",IF(R38>30,"Media",IF(C38<=Resumen!$B$3+15,"Media","Baja")))) | T32: Ana | U32: Sin acción | V32: Pendiente de confirmación de pago | Y32: 2025-T3 | Z32: =IF(AND(M38>0,C38<Resumen!$B$3),"Sí","No") | AA32: =IF(AND(L38>0,M38>0),"Sí","No") | AB32: =IF(J38="USD","Sí","No")
A33: FAC-00040 | B33: 45907 | C33: 45937 | D33: 45946 | E33: CL-019 | F33: Sierra Norte S.A.S. | G33: PyME servicios recurrentes | H33: SRV-002 | I33: Soporte operativo | J33: ARS | K33: 367000 | L33: 367000 | M33: 0 | N33: 1330 | O33: 0 | P33: 0 | Q33: =IF(M41<=0,"Cobrada",IF(L41>0,"Parcial",IF(C41<Resumen!$B$3,"Vencida",IF(C41<=Resumen!$B$3+15,"Por vencer","Pendiente")))) | R33: 0 | S33: =IF(M41<=0,"Sin prioridad",IF(R41>60,"Alta",IF(R41>30,"Media",IF(C41<=Resumen!$B$3+15,"Media","Baja")))) | T33: Carlos | U33: Sin acción | V33: Sin respuesta del cliente | Y33: 2025-T3 | Z33: =IF(AND(M41>0,C41<Resumen!$B$3),"Sí","No") | AA33: =IF(AND(L41>0,M41>0),"Sí","No") | AB33: =IF(J41="USD","Sí","No")
A34: FAC-00042 | B34: 45908 | C34: 45938 | D34: 45959 | E34: CL-008 | F34: Faro Administrativo S.A.S. | G34: PyME servicios recurrentes | H34: SRV-003 | I34: Consultoría de gestión | J34: USD | K34: 2400 | L34: 2400 | M34: 0 | N34: 1330 | O34: 0 | P34: 0 | Q34: =IF(M43<=0,"Cobrada",IF(L43>0,"Parcial",IF(C43<Resumen!$B$3,"Vencida",IF(C43<=Resumen!$B$3+15,"Por vencer","Pendiente")))) | R34: 0 | S34: =IF(M43<=0,"Sin prioridad",IF(R43>60,"Alta",IF(R43>30,"Media",IF(C43<=Resumen!$B$3+15,"Media","Baja")))) | T34: Sofía | U34: Sin acción | V34: En seguimiento administrativo | Y34: 2025-T3 | Z34: =IF(AND(M43>0,C43<Resumen!$B$3),"Sí","No") | AA34: =IF(AND(L43>0,M43>0),"Sí","No") | AB34: =IF(J43="USD","Sí","No")
A35: FAC-00027 | B35: 45909 | C35: 45954 | D35: 45990 | E35: CL-010 | F35: Horizonte Servicios S.R.L. | G35: PyME servicios recurrentes | H35: SRV-001 | I35: Abono mensual administrativo | J35: ARS | K35: 808000 | L35: 808000 | M35: 0 | N35: 1330 | O35: 0 | P35: 0 | Q35: =IF(M28<=0,"Cobrada",IF(L28>0,"Parcial",IF(C28<Resumen!$B$3,"Vencida",IF(C28<=Resumen!$B$3+15,"Por vencer","Pendiente")))) | R35: 0 | S35: =IF(M28<=0,"Sin prioridad",IF(R28>60,"Alta",IF(R28>30,"Media",IF(C28<=Resumen!$B$3+15,"Media","Baja")))) | T35: Matías | U35: Sin acción | V35: Cliente solicita reenvío de factura | Y35: 2025-T3 | Z35: =IF(AND(M28>0,C28<Resumen!$B$3),"Sí","No") | AA35: =IF(AND(L28>0,M28>0),"Sí","No") | AB35: =IF(J28="USD","Sí","No")
A36: FAC-00036 | B36: 45909 | C36: 45954 | D36: 45967 | E36: CL-007 | F36: Eje Comercial S.R.L. | G36: PyME servicios recurrentes | H36: SRV-001 | I36: Abono mensual administrativo | J36: ARS | K36: 912000 | L36: 912000 | M36: 0 | N36: 1330 | O36: 0 | P36: 0 | Q36: =IF(M37<=0,"Cobrada",IF(L37>0,"Parcial",IF(C37<Resumen!$B$3,"Vencida",IF(C37<=Resumen!$B$3+15,"Por vencer","Pendiente")))) | R36: 0 | S36: =IF(M37<=0,"Sin prioridad",IF(R37>60,"Alta",IF(R37>30,"Media",IF(C37<=Resumen!$B$3+15,"Media","Baja")))) | T36: Matías | U36: Sin acción | V36: Sin respuesta del cliente | Y36: 2025-T3 | Z36: =IF(AND(M37>0,C37<Resumen!$B$3),"Sí","No") | AA36: =IF(AND(L37>0,M37>0),"Sí","No") | AB36: =IF(J37="USD","Sí","No")
A37: FAC-00041 | B37: 45909 | C37: 45939 | D37: 45956 | E37: CL-008 | F37: Faro Administrativo S.A.S. | G37: PyME servicios recurrentes | H37: SRV-001 | I37: Abono mensual administrativo | J37: USD | K37: 850 | L37: 850 | M37: 0 | N37: 1330 | O37: 0 | P37: 0 | Q37: =IF(M42<=0,"Cobrada",IF(L42>0,"Parcial",IF(C42<Resumen!$B$3,"Vencida",IF(C42<=Resumen!$B$3+15,"Por vencer","Pendiente")))) | R37: 0 | S37: =IF(M42<=0,"Sin prioridad",IF(R42>60,"Alta",IF(R42>30,"Media",IF(C42<=Resumen!$B$3+15,"Media","Baja")))) | T37: Sofía | U37: Sin acción | V37: En seguimiento administrativo | Y37: 2025-T3 | Z37: =IF(AND(M42>0,C42<Resumen!$B$3),"Sí","No") | AA37: =IF(AND(L42>0,M42>0),"Sí","No") | AB37: =IF(J42="USD","Sí","No")
A38: FAC-00025 | B38: 45910 | C38: 45955 | E38: CL-016 | F38: Patagonia Gestión S.R.L. | G38: PyME servicios recurrentes | H38: SRV-001 | I38: Abono mensual administrativo | J38: ARS | K38: 817000 | L38: 0 | M38: 0 | N38: 1330 | O38: 0 | P38: 0 | Q38: =IF(M26<=0,"Cobrada",IF(L26>0,"Parcial",IF(C26<Resumen!$B$3,"Vencida",IF(C26<=Resumen!$B$3+15,"Por vencer","Pendiente")))) | R38: 0 | S38: =IF(M26<=0,"Sin prioridad",IF(R26>60,"Alta",IF(R26>30,"Media",IF(C26<=Resumen!$B$3+15,"Media","Baja")))) | T38: Matías | U38: Reenviar factura | Y38: 2025-T3 | Z38: =IF(AND(M26>0,C26<Resumen!$B$3),"Sí","No") | AA38: =IF(AND(L26>0,M26>0),"Sí","No") | AB38: =IF(J26="USD","Sí","No")
A39: FAC-00038 | B39: 45911 | C39: 45956 | E39: CL-007 | F39: Eje Comercial S.R.L. | G39: PyME servicios recurrentes | H39: SRV-004 | I39: Reporte mensual / tablero de control | J39: USD | K39: 1300 | L39: 0 | M39: 0 | N39: 1330 | O39: 0 | P39: 0 | Q39: =IF(M39<=0,"Cobrada",IF(L39>0,"Parcial",IF(C39<Resumen!$B$3,"Vencida",IF(C39<=Resumen!$B$3+15,"Por vencer","Pendiente")))) | R39: 0 | S39: =IF(M39<=0,"Sin prioridad",IF(R39>60,"Alta",IF(R39>30,"Media",IF(C39<=Resumen!$B$3+15,"Media","Baja")))) | T39: Matías | U39: Reenviar factura | V39: Pago prometido para próxima semana | Y39: 2025-T3 | Z39: =IF(AND(M39>0,C39<Resumen!$B$3),"Sí","No") | AA39: =IF(AND(L39>0,M39>0),"Sí","No") | AB39: =IF(J39="USD","Sí","No")
A40: FAC-00043 | B40: 45913 | C40: 45928 | D40: 45932 | E40: CL-011 | F40: Impulso Gestión S.A.S. | G40: PyME servicios recurrentes | H40: SRV-001 | I40: Abono mensual administrativo | J40: ARS | K40: 926000 | L40: 926000 | M40: 0 | N40: 1330 | O40: 0 | P40: 0 | Q40: =IF(M44<=0,"Cobrada",IF(L44>0,"Parcial",IF(C44<Resumen!$B$3,"Vencida",IF(C44<=Resumen!$B$3+15,"Por vencer","Pendiente")))) | R40: 0 | S40: =IF(M44<=0,"Sin prioridad",IF(R44>60,"Alta",IF(R44>30,"Media",IF(C44<=Resumen!$B$3+15,"Media","Baja")))) | T40: Carlos | U40: Sin acción | V40: Cliente solicita reenvío de factura | Y40: 2025-T3 | Z40: =IF(AND(M44>0,C44<Resumen!$B$3),"Sí","No") | AA40: =IF(AND(L44>0,M44>0),"Sí","No") | AB40: =IF(J44="USD","Sí","No")
...

Sheet Clientes
A1: id_cliente | B1: cliente | C1: tipo_cliente | D1: condicion_pago_dias | E1: perfil_pago | F1: responsable | H1: Selector y resumen por cliente
A2: {=_xlfn._xlws.SORT(_xlfn.UNIQUE(FacturasTable[id_cliente]))} | B2: =IF($A2="","",_xlfn.XLOOKUP($A2,FacturasTable[id_cliente],FacturasTable[cliente],"")) | C2: =IF($A2="","",_xlfn.XLOOKUP($A2,FacturasTable[id_cliente],FacturasTable[tipo_cliente],"")) | D2: =IF($A2="","",_xlfn.XLOOKUP($A2,FacturasTable[id_cliente],FacturasTable[fecha_vencimiento],"")-_xlfn.XLOOKUP($A2,FacturasTable[id_cliente],FacturasTable[fecha_emision],"")) | E2: =IF($A2="","",IF(AVERAGEIFS(FacturasTable[dias_atraso],FacturasTable[id_cliente],$A2,FacturasTable[dias_atraso],">0")>30,"Atraso medio",IF(AVERAGEIFS(FacturasTable[dias_atraso],FacturasTable[id_cliente],$A2,FacturasTable[dias_atraso],">0")>0,"Atraso leve","Paga en término"))) | F2: =IF($A2="","",_xlfn.XLOOKUP($A2,FacturasTable[id_cliente],FacturasTable[responsable],""))
A3: CL-002 | B3: =IF($A3="","",_xlfn.XLOOKUP($A3,FacturasTable[id_cliente],FacturasTable[cliente],"")) | C3: =IF($A3="","",_xlfn.XLOOKUP($A3,FacturasTable[id_cliente],FacturasTable[tipo_cliente],"")) | D3: =IF($A3="","",_xlfn.XLOOKUP($A3,FacturasTable[id_cliente],FacturasTable[fecha_vencimiento],"")-_xlfn.XLOOKUP($A3,FacturasTable[id_cliente],FacturasTable[fecha_emision],"")) | E3: =IF($A3="","",IF(AVERAGEIFS(FacturasTable[dias_atraso],FacturasTable[id_cliente],$A3,FacturasTable[dias_atraso],">0")>30,"Atraso medio",IF(AVERAGEIFS(FacturasTable[dias_atraso],FacturasTable[id_cliente],$A3,FacturasTable[dias_atraso],">0")>0,"Atraso leve","Paga en término"))) | F3: =IF($A3="","",_xlfn.XLOOKUP($A3,FacturasTable[id_cliente],FacturasTable[responsable],"")) | H3: Elegir cliente | I3: Punto Sur S.A.
A4: CL-003 | B4: =IF($A4="","",_xlfn.XLOOKUP($A4,FacturasTable[id_cliente],FacturasTable[cliente],"")) | C4: =IF($A4="","",_xlfn.XLOOKUP($A4,FacturasTable[id_cliente],FacturasTable[tipo_cliente],"")) | D4: =IF($A4="","",_xlfn.XLOOKUP($A4,FacturasTable[id_cliente],FacturasTable[fecha_vencimiento],"")-_xlfn.XLOOKUP($A4,FacturasTable[id_cliente],FacturasTable[fecha_emision],"")) | E4: =IF($A4="","",IF(AVERAGEIFS(FacturasTable[dias_atraso],FacturasTable[id_cliente],$A4,FacturasTable[dias_atraso],">0")>30,"Atraso medio",IF(AVERAGEIFS(FacturasTable[dias_atraso],FacturasTable[id_cliente],$A4,FacturasTable[dias_atraso],">0")>0,"Atraso leve","Paga en término"))) | F4: =IF($A4="","",_xlfn.XLOOKUP($A4,FacturasTable[id_cliente],FacturasTable[responsable],""))
A5: CL-004 | B5: =IF($A5="","",_xlfn.XLOOKUP($A5,FacturasTable[id_cliente],FacturasTable[cliente],"")) | C5: =IF($A5="","",_xlfn.XLOOKUP($A5,FacturasTable[id_cliente],FacturasTable[tipo_cliente],"")) | D5: =IF($A5="","",_xlfn.XLOOKUP($A5,FacturasTable[id_cliente],FacturasTable[fecha_vencimiento],"")-_xlfn.XLOOKUP($A5,FacturasTable[id_cliente],FacturasTable[fecha_emision],"")) | E5: =IF($A5="","",IF(AVERAGEIFS(FacturasTable[dias_atraso],FacturasTable[id_cliente],$A5,FacturasTable[dias_atraso],">0")>30,"Atraso medio",IF(AVERAGEIFS(FacturasTable[dias_atraso],FacturasTable[id_cliente],$A5,FacturasTable[dias_atraso],">0")>0,"Atraso leve","Paga en término"))) | F5: =IF($A5="","",_xlfn.XLOOKUP($A5,FacturasTable[id_cliente],FacturasTable[responsable],"")) | H5: id_cliente | I5: =IFERROR(_xlfn.XLOOKUP($I$3,$B$2:$B$999,$A$2:$A$999,""),"")
A6: CL-005 | B6: =IF($A6="","",_xlfn.XLOOKUP($A6,FacturasTable[id_cliente],FacturasTable[cliente],"")) | C6: =IF($A6="","",_xlfn.XLOOKUP($A6,FacturasTable[id_cliente],FacturasTable[tipo_cliente],"")) | D6: =IF($A6="","",_xlfn.XLOOKUP($A6,FacturasTable[id_cliente],FacturasTable[fecha_vencimiento],"")-_xlfn.XLOOKUP($A6,FacturasTable[id_cliente],FacturasTable[fecha_emision],"")) | E6: =IF($A6="","",IF(AVERAGEIFS(FacturasTable[dias_atraso],FacturasTable[id_cliente],$A6,FacturasTable[dias_atraso],">0")>30,"Atraso medio",IF(AVERAGEIFS(FacturasTable[dias_atraso],FacturasTable[id_cliente],$A6,FacturasTable[dias_atraso],">0")>0,"Atraso leve","Paga en término"))) | F6: =IF($A6="","",_xlfn.XLOOKUP($A6,FacturasTable[id_cliente],FacturasTable[responsable],"")) | H6: tipo_cliente | I6: =IF($I$5="","",_xlfn.XLOOKUP($I$5,$A$2:$A$999,$C$2:$C$999,""))
A7: CL-006 | B7: =IF($A7="","",_xlfn.XLOOKUP($A7,FacturasTable[id_cliente],FacturasTable[cliente],"")) | C7: =IF($A7="","",_xlfn.XLOOKUP($A7,FacturasTable[id_cliente],FacturasTable[tipo_cliente],"")) | D7: =IF($A7="","",_xlfn.XLOOKUP($A7,FacturasTable[id_cliente],FacturasTable[fecha_vencimiento],"")-_xlfn.XLOOKUP($A7,FacturasTable[id_cliente],FacturasTable[fecha_emision],"")) | E7: =IF($A7="","",IF(AVERAGEIFS(FacturasTable[dias_atraso],FacturasTable[id_cliente],$A7,FacturasTable[dias_atraso],">0")>30,"Atraso medio",IF(AVERAGEIFS(FacturasTable[dias_atraso],FacturasTable[id_cliente],$A7,FacturasTable[dias_atraso],">0")>0,"Atraso leve","Paga en término"))) | F7: =IF($A7="","",_xlfn.XLOOKUP($A7,FacturasTable[id_cliente],FacturasTable[responsable],"")) | H7: responsable | I7: =IF($I$5="","",_xlfn.XLOOKUP($I$5,$A$2:$A$999,$F$2:$F$999,""))
A8: CL-007 | B8: =IF($A8="","",_xlfn.XLOOKUP($A8,FacturasTable[id_cliente],FacturasTable[cliente],"")) | C8: =IF($A8="","",_xlfn.XLOOKUP($A8,FacturasTable[id_cliente],FacturasTable[tipo_cliente],"")) | D8: =IF($A8="","",_xlfn.XLOOKUP($A8,FacturasTable[id_cliente],FacturasTable[fecha_vencimiento],"")-_xlfn.XLOOKUP($A8,FacturasTable[id_cliente],FacturasTable[fecha_emision],"")) | E8: =IF($A8="","",IF(AVERAGEIFS(FacturasTable[dias_atraso],FacturasTable[id_cliente],$A8,FacturasTable[dias_atraso],">0")>30,"Atraso medio",IF(AVERAGEIFS(FacturasTable[dias_atraso],FacturasTable[id_cliente],$A8,FacturasTable[dias_atraso],">0")>0,"Atraso leve","Paga en término"))) | F8: =IF($A8="","",_xlfn.XLOOKUP($A8,FacturasTable[id_cliente],FacturasTable[responsable],"")) | H8: condición_pago_días | I8: =IF($I$5="","",_xlfn.XLOOKUP($I$5,$A$2:$A$999,$D$2:$D$999,""))
A9: CL-008 | B9: =IF($A9="","",_xlfn.XLOOKUP($A9,FacturasTable[id_cliente],FacturasTable[cliente],"")) | C9: =IF($A9="","",_xlfn.XLOOKUP($A9,FacturasTable[id_cliente],FacturasTable[tipo_cliente],"")) | D9: =IF($A9="","",_xlfn.XLOOKUP($A9,FacturasTable[id_cliente],FacturasTable[fecha_vencimiento],"")-_xlfn.XLOOKUP($A9,FacturasTable[id_cliente],FacturasTable[fecha_emision],"")) | E9: =IF($A9="","",IF(AVERAGEIFS(FacturasTable[dias_atraso],FacturasTable[id_cliente],$A9,FacturasTable[dias_atraso],">0")>30,"Atraso medio",IF(AVERAGEIFS(FacturasTable[dias_atraso],FacturasTable[id_cliente],$A9,FacturasTable[dias_atraso],">0")>0,"Atraso leve","Paga en término"))) | F9: =IF($A9="","",_xlfn.XLOOKUP($A9,FacturasTable[id_cliente],FacturasTable[responsable],""))
A10: CL-009 | B10: =IF($A10="","",_xlfn.XLOOKUP($A10,FacturasTable[id_cliente],FacturasTable[cliente],"")) | C10: =IF($A10="","",_xlfn.XLOOKUP($A10,FacturasTable[id_cliente],FacturasTable[tipo_cliente],"")) | D10: =IF($A10="","",_xlfn.XLOOKUP($A10,FacturasTable[id_cliente],FacturasTable[fecha_vencimiento],"")-_xlfn.XLOOKUP($A10,FacturasTable[id_cliente],FacturasTable[fecha_emision],"")) | E10: =IF($A10="","",IF(AVERAGEIFS(FacturasTable[dias_atraso],FacturasTable[id_cliente],$A10,FacturasTable[dias_atraso],">0")>30,"Atraso medio",IF(AVERAGEIFS(FacturasTable[dias_atraso],FacturasTable[id_cliente],$A10,FacturasTable[dias_atraso],">0")>0,"Atraso leve","Paga en término"))) | F10: =IF($A10="","",_xlfn.XLOOKUP($A10,FacturasTable[id_cliente],FacturasTable[responsable],"")) | H10: total_facturado_eq_ars | I10: =IF($I$5="","",SUMIFS(FacturasTable[importe_equivalente_ars],FacturasTable[id_cliente],$I$5))
A11: CL-010 | B11: =IF($A11="","",_xlfn.XLOOKUP($A11,FacturasTable[id_cliente],FacturasTable[cliente],"")) | C11: =IF($A11="","",_xlfn.XLOOKUP($A11,FacturasTable[id_cliente],FacturasTable[tipo_cliente],"")) | D11: =IF($A11="","",_xlfn.XLOOKUP($A11,FacturasTable[id_cliente],FacturasTable[fecha_vencimiento],"")-_xlfn.XLOOKUP($A11,FacturasTable[id_cliente],FacturasTable[fecha_emision],"")) | E11: =IF($A11="","",IF(AVERAGEIFS(FacturasTable[dias_atraso],FacturasTable[id_cliente],$A11,FacturasTable[dias_atraso],">0")>30,"Atraso medio",IF(AVERAGEIFS(FacturasTable[dias_atraso],FacturasTable[id_cliente],$A11,FacturasTable[dias_atraso],">0")>0,"Atraso leve","Paga en término"))) | F11: =IF($A11="","",_xlfn.XLOOKUP($A11,FacturasTable[id_cliente],FacturasTable[responsable],"")) | H11: total_cobrado_eq_ars | I11: =IF($I$5="","",$I$10-$I$12)
A12: CL-011 | B12: =IF($A12="","",_xlfn.XLOOKUP($A12,FacturasTable[id_cliente],FacturasTable[cliente],"")) | C12: =IF($A12="","",_xlfn.XLOOKUP($A12,FacturasTable[id_cliente],FacturasTable[tipo_cliente],"")) | D12: =IF($A12="","",_xlfn.XLOOKUP($A12,FacturasTable[id_cliente],FacturasTable[fecha_vencimiento],"")-_xlfn.XLOOKUP($A12,FacturasTable[id_cliente],FacturasTable[fecha_emision],"")) | E12: =IF($A12="","",IF(AVERAGEIFS(FacturasTable[dias_atraso],FacturasTable[id_cliente],$A12,FacturasTable[dias_atraso],">0")>30,"Atraso medio",IF(AVERAGEIFS(FacturasTable[dias_atraso],FacturasTable[id_cliente],$A12,FacturasTable[dias_atraso],">0")>0,"Atraso leve","Paga en término"))) | F12: =IF($A12="","",_xlfn.XLOOKUP($A12,FacturasTable[id_cliente],FacturasTable[responsable],"")) | H12: saldo_pendiente_eq_ars | I12: =IF($I$5="","",SUMIFS(FacturasTable[saldo_equivalente_ars],FacturasTable[id_cliente],$I$5))
A13: CL-012 | B13: =IF($A13="","",_xlfn.XLOOKUP($A13,FacturasTable[id_cliente],FacturasTable[cliente],"")) | C13: =IF($A13="","",_xlfn.XLOOKUP($A13,FacturasTable[id_cliente],FacturasTable[tipo_cliente],"")) | D13: =IF($A13="","",_xlfn.XLOOKUP($A13,FacturasTable[id_cliente],FacturasTable[fecha_vencimiento],"")-_xlfn.XLOOKUP($A13,FacturasTable[id_cliente],FacturasTable[fecha_emision],"")) | E13: =IF($A13="","",IF(AVERAGEIFS(FacturasTable[dias_atraso],FacturasTable[id_cliente],$A13,FacturasTable[dias_atraso],">0")>30,"Atraso medio",IF(AVERAGEIFS(FacturasTable[dias_atraso],FacturasTable[id_cliente],$A13,FacturasTable[dias_atraso],">0")>0,"Atraso leve","Paga en término"))) | F13: =IF($A13="","",_xlfn.XLOOKUP($A13,FacturasTable[id_cliente],FacturasTable[responsable],"")) | H13: saldo_pendiente_usd | I13: =IF($I$5="","",SUMIFS(FacturasTable[saldo_pendiente],FacturasTable[id_cliente],$I$5,FacturasTable[moneda],"USD"))
A14: CL-013 | B14: =IF($A14="","",_xlfn.XLOOKUP($A14,FacturasTable[id_cliente],FacturasTable[cliente],"")) | C14: =IF($A14="","",_xlfn.XLOOKUP($A14,FacturasTable[id_cliente],FacturasTable[tipo_cliente],"")) | D14: =IF($A14="","",_xlfn.XLOOKUP($A14,FacturasTable[id_cliente],FacturasTable[fecha_vencimiento],"")-_xlfn.XLOOKUP($A14,FacturasTable[id_cliente],FacturasTable[fecha_emision],"")) | E14: =IF($A14="","",IF(AVERAGEIFS(FacturasTable[dias_atraso],FacturasTable[id_cliente],$A14,FacturasTable[dias_atraso],">0")>30,"Atraso medio",IF(AVERAGEIFS(FacturasTable[dias_atraso],FacturasTable[id_cliente],$A14,FacturasTable[dias_atraso],">0")>0,"Atraso leve","Paga en término"))) | F14: =IF($A14="","",_xlfn.XLOOKUP($A14,FacturasTable[id_cliente],FacturasTable[responsable],"")) | H14: facturas_abiertas | I14: =IF($I$5="","",COUNTIFS(FacturasTable[id_cliente],$I$5,FacturasTable[saldo_pendiente],">0"))
A15: CL-014 | B15: =IF($A15="","",_xlfn.XLOOKUP($A15,FacturasTable[id_cliente],FacturasTable[cliente],"")) | C15: =IF($A15="","",_xlfn.XLOOKUP($A15,FacturasTable[id_cliente],FacturasTable[tipo_cliente],"")) | D15: =IF($A15="","",_xlfn.XLOOKUP($A15,FacturasTable[id_cliente],FacturasTable[fecha_vencimiento],"")-_xlfn.XLOOKUP($A15,FacturasTable[id_cliente],FacturasTable[fecha_emision],"")) | E15: =IF($A15="","",IF(AVERAGEIFS(FacturasTable[dias_atraso],FacturasTable[id_cliente],$A15,FacturasTable[dias_atraso],">0")>30,"Atraso medio",IF(AVERAGEIFS(FacturasTable[dias_atraso],FacturasTable[id_cliente],$A15,FacturasTable[dias_atraso],">0")>0,"Atraso leve","Paga en término"))) | F15: =IF($A15="","",_xlfn.XLOOKUP($A15,FacturasTable[id_cliente],FacturasTable[responsable],"")) | H15: facturas_vencidas | I15: =IF($I$5="","",COUNTIFS(FacturasTable[id_cliente],$I$5,FacturasTable[vencida_si_no],"Sí"))
A16: CL-015 | B16: =IF($A16="","",_xlfn.XLOOKUP($A16,FacturasTable[id_cliente],FacturasTable[cliente],"")) | C16: =IF($A16="","",_xlfn.XLOOKUP($A16,FacturasTable[id_cliente],FacturasTable[tipo_cliente],"")) | D16: =IF($A16="","",_xlfn.XLOOKUP($A16,FacturasTable[id_cliente],FacturasTable[fecha_vencimiento],"")-_xlfn.XLOOKUP($A16,FacturasTable[id_cliente],FacturasTable[fecha_emision],"")) | E16: =IF($A16="","",IF(AVERAGEIFS(FacturasTable[dias_atraso],FacturasTable[id_cliente],$A16,FacturasTable[dias_atraso],">0")>30,"Atraso medio",IF(AVERAGEIFS(FacturasTable[dias_atraso],FacturasTable[id_cliente],$A16,FacturasTable[dias_atraso],">0")>0,"Atraso leve","Paga en término"))) | F16: =IF($A16="","",_xlfn.XLOOKUP($A16,FacturasTable[id_cliente],FacturasTable[responsable],"")) | H16: mora_promedio_días | I16: =IFERROR(AVERAGEIFS(FacturasTable[dias_atraso],FacturasTable[id_cliente],$I$5,FacturasTable[dias_atraso],">0"),0)
A17: CL-016 | B17: =IF($A17="","",_xlfn.XLOOKUP($A17,FacturasTable[id_cliente],FacturasTable[cliente],"")) | C17: =IF($A17="","",_xlfn.XLOOKUP($A17,FacturasTable[id_cliente],FacturasTable[tipo_cliente],"")) | D17: =IF($A17="","",_xlfn.XLOOKUP($A17,FacturasTable[id_cliente],FacturasTable[fecha_vencimiento],"")-_xlfn.XLOOKUP($A17,FacturasTable[id_cliente],FacturasTable[fecha_emision],"")) | E17: =IF($A17="","",IF(AVERAGEIFS(FacturasTable[dias_atraso],FacturasTable[id_cliente],$A17,FacturasTable[dias_atraso],">0")>30,"Atraso medio",IF(AVERAGEIFS(FacturasTable[dias_atraso],FacturasTable[id_cliente],$A17,FacturasTable[dias_atraso],">0")>0,"Atraso leve","Paga en término"))) | F17: =IF($A17="","",_xlfn.XLOOKUP($A17,FacturasTable[id_cliente],FacturasTable[responsable],"")) | H17: última_factura | I17: =IF($I$5="","",_xlfn.MAXIFS(FacturasTable[fecha_emision],FacturasTable[id_cliente],$I$5))
A18: CL-017 | B18: =IF($A18="","",_xlfn.XLOOKUP($A18,FacturasTable[id_cliente],FacturasTable[cliente],"")) | C18: =IF($A18="","",_xlfn.XLOOKUP($A18,FacturasTable[id_cliente],FacturasTable[tipo_cliente],"")) | D18: =IF($A18="","",_xlfn.XLOOKUP($A18,FacturasTable[id_cliente],FacturasTable[fecha_vencimiento],"")-_xlfn.XLOOKUP($A18,FacturasTable[id_cliente],FacturasTable[fecha_emision],"")) | E18: =IF($A18="","",IF(AVERAGEIFS(FacturasTable[dias_atraso],FacturasTable[id_cliente],$A18,FacturasTable[dias_atraso],">0")>30,"Atraso medio",IF(AVERAGEIFS(FacturasTable[dias_atraso],FacturasTable[id_cliente],$A18,FacturasTable[dias_atraso],">0")>0,"Atraso leve","Paga en término"))) | F18: =IF($A18="","",_xlfn.XLOOKUP($A18,FacturasTable[id_cliente],FacturasTable[responsable],"")) | H18: próxima_acción | I18: Reclamar saldo parcial
A19: CL-018 | B19: =IF($A19="","",_xlfn.XLOOKUP($A19,FacturasTable[id_cliente],FacturasTable[cliente],"")) | C19: =IF($A19="","",_xlfn.XLOOKUP($A19,FacturasTable[id_cliente],FacturasTable[tipo_cliente],"")) | D19: =IF($A19="","",_xlfn.XLOOKUP($A19,FacturasTable[id_cliente],FacturasTable[fecha_vencimiento],"")-_xlfn.XLOOKUP($A19,FacturasTable[id_cliente],FacturasTable[fecha_emision],"")) | E19: =IF($A19="","",IF(AVERAGEIFS(FacturasTable[dias_atraso],FacturasTable[id_cliente],$A19,FacturasTable[dias_atraso],">0")>30,"Atraso medio",IF(AVERAGEIFS(FacturasTable[dias_atraso],FacturasTable[id_cliente],$A19,FacturasTable[dias_atraso],">0")>0,"Atraso leve","Paga en término"))) | F19: =IF($A19="","",_xlfn.XLOOKUP($A19,FacturasTable[id_cliente],FacturasTable[responsable],"")) | H19: vencimiento_más_antiguo_pendiente | I19: =IFERROR(_xlfn.MINIFS(Facturas!$C$2:$C$237,Facturas!$E$2:$E$237,$I$5,Facturas!$M$2:$M$237,">0"),"")
A20: CL-019 | B20: =IF($A20="","",_xlfn.XLOOKUP($A20,FacturasTable[id_cliente],FacturasTable[cliente],"")) | C20: =IF($A20="","",_xlfn.XLOOKUP($A20,FacturasTable[id_cliente],FacturasTable[tipo_cliente],"")) | D20: =IF($A20="","",_xlfn.XLOOKUP($A20,FacturasTable[id_cliente],FacturasTable[fecha_vencimiento],"")-_xlfn.XLOOKUP($A20,FacturasTable[id_cliente],FacturasTable[fecha_emision],"")) | E20: =IF($A20="","",IF(AVERAGEIFS(FacturasTable[dias_atraso],FacturasTable[id_cliente],$A20,FacturasTable[dias_atraso],">0")>30,"Atraso medio",IF(AVERAGEIFS(FacturasTable[dias_atraso],FacturasTable[id_cliente],$A20,FacturasTable[dias_atraso],">0")>0,"Atraso leve","Paga en término"))) | F20: =IF($A20="","",_xlfn.XLOOKUP($A20,FacturasTable[id_cliente],FacturasTable[responsable],"")) | H20: tiene_deuda | I20: =IF($I$12>0,"Sí","No")
A21: CL-020 | B21: =IF($A21="","",_xlfn.XLOOKUP($A21,FacturasTable[id_cliente],FacturasTable[cliente],"")) | C21: =IF($A21="","",_xlfn.XLOOKUP($A21,FacturasTable[id_cliente],FacturasTable[tipo_cliente],"")) | D21: =IF($A21="","",_xlfn.XLOOKUP($A21,FacturasTable[id_cliente],FacturasTable[fecha_vencimiento],"")-_xlfn.XLOOKUP($A21,FacturasTable[id_cliente],FacturasTable[fecha_emision],"")) | E21: =IF($A21="","",IF(AVERAGEIFS(FacturasTable[dias_atraso],FacturasTable[id_cliente],$A21,FacturasTable[dias_atraso],">0")>30,"Atraso medio",IF(AVERAGEIFS(FacturasTable[dias_atraso],FacturasTable[id_cliente],$A21,FacturasTable[dias_atraso],">0")>0,"Atraso leve","Paga en término"))) | F21: =IF($A21="","",_xlfn.XLOOKUP($A21,FacturasTable[id_cliente],FacturasTable[responsable],""))
A22: CL-021 | B22: =IF($A22="","",_xlfn.XLOOKUP($A22,FacturasTable[id_cliente],FacturasTable[cliente],"")) | C22: =IF($A22="","",_xlfn.XLOOKUP($A22,FacturasTable[id_cliente],FacturasTable[tipo_cliente],"")) | D22: =IF($A22="","",_xlfn.XLOOKUP($A22,FacturasTable[id_cliente],FacturasTable[fecha_vencimiento],"")-_xlfn.XLOOKUP($A22,FacturasTable[id_cliente],FacturasTable[fecha_emision],"")) | E22: =IF($A22="","",IF(AVERAGEIFS(FacturasTable[dias_atraso],FacturasTable[id_cliente],$A22,FacturasTable[dias_atraso],">0")>30,"Atraso medio",IF(AVERAGEIFS(FacturasTable[dias_atraso],FacturasTable[id_cliente],$A22,FacturasTable[dias_atraso],">0")>0,"Atraso leve","Paga en término"))) | F22: =IF($A22="","",_xlfn.XLOOKUP($A22,FacturasTable[id_cliente],FacturasTable[responsable],""))
A23: CL-022 | B23: =IF($A23="","",_xlfn.XLOOKUP($A23,FacturasTable[id_cliente],FacturasTable[cliente],"")) | C23: =IF($A23="","",_xlfn.XLOOKUP($A23,FacturasTable[id_cliente],FacturasTable[tipo_cliente],"")) | D23: =IF($A23="","",_xlfn.XLOOKUP($A23,FacturasTable[id_cliente],FacturasTable[fecha_vencimiento],"")-_xlfn.XLOOKUP($A23,FacturasTable[id_cliente],FacturasTable[fecha_emision],"")) | E23: =IF($A23="","",IF(AVERAGEIFS(FacturasTable[dias_atraso],FacturasTable[id_cliente],$A23,FacturasTable[dias_atraso],">0")>30,"Atraso medio",IF(AVERAGEIFS(FacturasTable[dias_atraso],FacturasTable[id_cliente],$A23,FacturasTable[dias_atraso],">0")>0,"Atraso leve","Paga en término"))) | F23: =IF($A23="","",_xlfn.XLOOKUP($A23,FacturasTable[id_cliente],FacturasTable[responsable],""))
A24: CL-023 | B24: =IF($A24="","",_xlfn.XLOOKUP($A24,FacturasTable[id_cliente],FacturasTable[cliente],"")) | C24: =IF($A24="","",_xlfn.XLOOKUP($A24,FacturasTable[id_cliente],FacturasTable[tipo_cliente],"")) | D24: =IF($A24="","",_xlfn.XLOOKUP($A24,FacturasTable[id_cliente],FacturasTable[fecha_vencimiento],"")-_xlfn.XLOOKUP($A24,FacturasTable[id_cliente],FacturasTable[fecha_emision],"")) | E24: =IF($A24="","",IF(AVERAGEIFS(FacturasTable[dias_atraso],FacturasTable[id_cliente],$A24,FacturasTable[dias_atraso],">0")>30,"Atraso medio",IF(AVERAGEIFS(FacturasTable[dias_atraso],FacturasTable[id_cliente],$A24,FacturasTable[dias_atraso],">0")>0,"Atraso leve","Paga en término"))) | F24: =IF($A24="","",_xlfn.XLOOKUP($A24,FacturasTable[id_cliente],FacturasTable[responsable],""))
A25: CL-024 | B25: =IF($A25="","",_xlfn.XLOOKUP($A25,FacturasTable[id_cliente],FacturasTable[cliente],"")) | C25: =IF($A25="","",_xlfn.XLOOKUP($A25,FacturasTable[id_cliente],FacturasTable[tipo_cliente],"")) | D25: =IF($A25="","",_xlfn.XLOOKUP($A25,FacturasTable[id_cliente],FacturasTable[fecha_vencimiento],"")-_xlfn.XLOOKUP($A25,FacturasTable[id_cliente],FacturasTable[fecha_emision],"")) | E25: =IF($A25="","",IF(AVERAGEIFS(FacturasTable[dias_atraso],FacturasTable[id_cliente],$A25,FacturasTable[dias_atraso],">0")>30,"Atraso medio",IF(AVERAGEIFS(FacturasTable[dias_atraso],FacturasTable[id_cliente],$A25,FacturasTable[dias_atraso],">0")>0,"Atraso leve","Paga en término"))) | F25: =IF($A25="","",_xlfn.XLOOKUP($A25,FacturasTable[id_cliente],FacturasTable[responsable],""))
B26: =IF($A26="","",_xlfn.XLOOKUP($A26,FacturasTable[id_cliente],FacturasTable[cliente],"")) | C26: =IF($A26="","",_xlfn.XLOOKUP($A26,FacturasTable[id_cliente],FacturasTable[tipo_cliente],"")) | D26: =IF($A26="","",_xlfn.XLOOKUP($A26,FacturasTable[id_cliente],FacturasTable[fecha_vencimiento],"")-_xlfn.XLOOKUP($A26,FacturasTable[id_cliente],FacturasTable[fecha_emision],"")) | E26: =IF($A26="","",IF(AVERAGEIFS(FacturasTable[dias_atraso],FacturasTable[id_cliente],$A26,FacturasTable[dias_atraso],">0")>30,"Atraso medio",IF(AVERAGEIFS(FacturasTable[dias_atraso],FacturasTable[id_cliente],$A26,FacturasTable[dias_atraso],">0")>0,"Atraso leve","Paga en término"))) | F26: =IF($A26="","",_xlfn.XLOOKUP($A26,FacturasTable[id_cliente],FacturasTable[responsable],""))
B27: =IF($A27="","",_xlfn.XLOOKUP($A27,FacturasTable[id_cliente],FacturasTable[cliente],"")) | C27: =IF($A27="","",_xlfn.XLOOKUP($A27,FacturasTable[id_cliente],FacturasTable[tipo_cliente],"")) | D27: =IF($A27="","",_xlfn.XLOOKUP($A27,FacturasTable[id_cliente],FacturasTable[fecha_vencimiento],"")-_xlfn.XLOOKUP($A27,FacturasTable[id_cliente],FacturasTable[fecha_emision],"")) | E27: =IF($A27="","",IF(AVERAGEIFS(FacturasTable[dias_atraso],FacturasTable[id_cliente],$A27,FacturasTable[dias_atraso],">0")>30,"Atraso medio",IF(AVERAGEIFS(FacturasTable[dias_atraso],FacturasTable[id_cliente],$A27,FacturasTable[dias_atraso],">0")>0,"Atraso leve","Paga en término"))) | F27: =IF($A27="","",_xlfn.XLOOKUP($A27,FacturasTable[id_cliente],FacturasTable[responsable],""))
B28: =IF($A28="","",_xlfn.XLOOKUP($A28,FacturasTable[id_cliente],FacturasTable[cliente],"")) | C28: =IF($A28="","",_xlfn.XLOOKUP($A28,FacturasTable[id_cliente],FacturasTable[tipo_cliente],"")) | D28: =IF($A28="","",_xlfn.XLOOKUP($A28,FacturasTable[id_cliente],FacturasTable[fecha_vencimiento],"")-_xlfn.XLOOKUP($A28,FacturasTable[id_cliente],FacturasTable[fecha_emision],"")) | E28: =IF($A28="","",IF(AVERAGEIFS(FacturasTable[dias_atraso],FacturasTable[id_cliente],$A28,FacturasTable[dias_atraso],">0")>30,"Atraso medio",IF(AVERAGEIFS(FacturasTable[dias_atraso],FacturasTable[id_cliente],$A28,FacturasTable[dias_atraso],">0")>0,"Atraso leve","Paga en término"))) | F28: =IF($A28="","",_xlfn.XLOOKUP($A28,FacturasTable[id_cliente],FacturasTable[responsable],""))

Sheet Servicios
